Workbook
Name Excel_BuiltIn__FilterDatabase: '6.Curva ABC'!$B$13:$K$64
Name Excel_BuiltIn_Print_Area: '7. Laudo de Habitabitabilidade'!$B$2:$AJ$29

Sheet 0. Dados
A7: Endereço: | F7: São José do Capricho, em Flexeiras/AL | X7: SIPRA | AA7: AL018600000007
A9: Titular 1: | D9: Angelo Santos | X9: CPF | Z9: 11277828431
A11: Titular 2: | D11: Carol Souza | X11: CPF | Z11: 12345678901
X12: Data da Vistoria
X13: 2026-07-21

Sheet 1. Proposta
B7: 1 - IDENTIFICAÇÃO
C9: Programa | W9: Programa
C10: Crédito Instação na modalidade reforma | W10: Aquisição de Material de Construção
C12: Assentamento | R12: Código Sipra | W12: Sub Modalidade | AF12: Custo (R$)
C13: ='0. Dados'!F7 -> São José do Capricho, em Flexeiras/AL | R13: ='0. Dados'!AA7 -> AL018600000007 | W13: Ref. e/ou Ampliação | AF13: 50000
C15: T1 | F15: ='0. Dados'!D9 -> Angelo Santos | AA15: CPF | AD15: ='0. Dados'!Z9 -> 11277828431
C17: T2 | F17: ='0. Dados'!D11 -> Carol Souza | AA17: CPF | AD17: ='0. Dados'!Z11 -> 12345678901
B19: O imóvel objeto desta proposta de intervenção possui georreferenciamento devidamente atestado via registro fotográfico. Certifica-se que a área não apresentae restrições ambientais, inexistindo sobreposição com Áreas de Preservação Permanente (APP) ou Reserva Legal (RL). A implantação cumpre integralmente os afastamentos regulamentares e faixas não edificáveis relativos a corpos hídricos e nascentes, bem como as distâncias sanitárias exigidas para instalações de zootecnia intensiva (suinocultura e avicultura), em estrita observância à legislação ambiental vigente.
B21: 2 - SITUAÇÃO DE FORNECIMENTO DE SERVIÇOS PÚBLICOS
C23: Água | I23: Água fornecida pela concessionaria
C24: Esgot. Sanitário | I24: Fossa para destinação de dejetos sólidos e liberação no terreno de águas cinzas
C25: Energia elétrica | I25: Energia fornecida pela concessionaria
B28: 2.1 - Situação da unidade habitacional
B30: A unidade existente requer reparos preventivos/corretivos em diversos sistemas construtivos. O escopo inclui a adequação das redes de infraestrutura (elétrica e hidráulica), tratamento de superfícies e acabamentos, e estanqueidade do telhado. Tais medidas são indispensáveis para garantir a estabilidade da edificação e a conformidade com as normas de salubridade e segurança habitacional."
B31: 3 - RELAÇÃO DE ANEXOS
E33: Registro Fotográfico da Unidade | U33: Ata da Associação
E35: Croqui da unidade | U35: ART
E37: Orçamentos | U37: Outros
E39: Declaração de aceitação de serviços
X45: _________________________________
D46: ='0. Dados'!D9 -> Angelo Santos | X46: Antonio Cleverson da Costa Silva
X47: Engenheiro Civil
X48: CREA 021697043-1

Sheet 2. Croqui Padrão
B5: ='0. Dados'!F7 -> São José do Capricho, em Flexeiras/AL
B6: =TODAY() -> 46224
B8: Nome do beneficiário | AA8: CPF
B9: ='0. Dados'!D9 -> Angelo Santos | AA9: ='0. Dados'!Z9 -> 11277828431
C14: De modo geral, as unidades habitacionais situadas nos assentamentos do INCRA no estado de Alagoas seguem um padrão arquitetônico tipificado. Tratam-se de residências unifamiliares com área construída de aproximadamente 42,00 m², cujo programa de necessidades compreende sala de estar, cozinha, dois dormitórios e sanitário social. É comum observar variações pontuais, como a inclusão de alpendres frontais ou laterais, que conferem transição entre os espaços internos e externos.

Sheet 3. Edificação
A1: RELATÓRIO FOTOGRÁFICO
A2: ='2. Croqui Padrão'!B5:AJ5 -> #VALUE!
V3: =TODAY() -> 46224
A5: Nome do beneficiário | Z5: CPF
A6: ='0. Dados'!D9 -> Angelo Santos | Z6: ='0. Dados'!Z9:AH9 -> 11277828431

Sheet 4. Documentos
A1: DOCUMENTOS
A2: ='2. Croqui Padrão'!B5:AJ5 -> #VALUE!
V3: =TODAY() -> 46224
A5: Nome do beneficiário | Z5: CPF
A6: ='0. Dados'!D9 -> Angelo Santos | Z6: ='0. Dados'!Z9:AH9 -> 11277828431

Sheet 3. Memorial Descritivo
B6: ='0. Dados'!F7 -> São José do Capricho, em Flexeiras/AL
Y7: =TODAY() -> 46224
B8: Nome do beneficiário | AA8: CPF
B9: ='0. Dados'!D9 -> Angelo Santos | AA9: ='0. Dados'!Z9 -> 11277828431
B10: A elaboração do presente orçamento fundamenta-se nas diretrizes técnicas e metodologias construtivas vigentes, balizada pelas composições de custos unitários do SINAPI (Sistema Nacional de Pesquisa de Custos e Índices da Construção Civil) e do ORSE (Orçamento de Obras de Sergipe). Tal conformidade estende-se rigorosamente às especificações técnicas dos insumos aplicados. A execução dos serviços observará estritamente as Normas Brasileiras (NBR/ABNT), as boas práticas de engenharia e a cronologia da metodologia executiva proposta para o empreendimento.
B11: 1 DOS SERVIÇOS DE REFORMA | AK11: x
B12: 1.1 Intervenções Estruturais | AK12: x
B13: A) | C13: Reparos em alvenaria e reboco (até 30% da área de pintura): Serão executados serviços de recuperação de fachada, compreendendo o tratamento de patologias estruturais e superficiais. O escopo inclui a recomposição do revestimento argamassado, reparos pontuais em alvenaria de vedação e a estancamento de fissuras e trincas através de selagem técnica para garantir a integridade do substrato. | AK13: x
B14: B) | C14: Revisão de telhado: Será executado serviços de manutenção preventiva e corretiva da cobertura da edificação. Objetivando garantir a estanqueidade, a integridade estrutural e o prolongamento da vida útil do sistema de cobertura com a substituição de telhas e madeiras que apresentarem aspectos que comprometam a segurança do telhado. | AK14: x
B15: C) | C15: Fabricação de lage do banheiro: Será executada laje de cobertura do banheiro, adotando o sistema de laje pré-fabricada treliçada, dimensionada para suportar as cargas permanentes e cargas acidentais em acordo NBR 6120. | AK15: x
B16: D) | C16: Calçada: Sera executado o serviço de construção da calçada ao redor da edificação, visando a proteção das fundações e da base das alvenarias contra possivel a infiltração direta de águas pluviais que possam comprometer a capacidade de carga do solo de fundação ou causar recalques, além de evitar o surgimento de umidade ascensional nas paredes.
B17: E) | C17: Piso e contrapiso: O objetivo deste item é estabelecer as condições de execução para as camadas de regularização (contrapiso) e o acabamento final de piso, garantindo a aderência, o nivelamento e o caimento adequado para o escoamento de águas. O contrapiso será executado em argamassa de cimento e areia no traço 1:4 em volume, com consistência de "farofa" úmida. | AK17: x
B18: 1.2 Sistema Elétrico | AK18: x
B19: F) | C19: Instalações no sistema Eletrico: Sera executada as instalações eletricas em acordo com a NBR 5410 (Instalações Elétricas de Baixa Tensão), visando garantir a segurança e funcionalidade, Observando. Padrão de Entrada; Quadro de Distribuição; Eletrodutos; Caixas de passagem; Cabeamento e Condutores; Dispositivos de Proteção; Pontos de Utilização e Acabamentos e Testes Finais.
B20: 1.3 Sistema Hidro-sanitátio | AK20: x
B21: G) | C21: Banheiro: Execução de pontos de utilização de água fria e pontos de contribuição de esgoto sanitário, com instalação de vaso sanitário, lavatorio e chuveiro. | AK21: x
B22: H) | C22: Cozinha: Execução de pontos de utilização de água fria e pontos de contribuição de esgoto sanitário, com instalação de pia em marmore sintético.
B23: I) | C23: Área de Serviço: Execução de pontos de utilização de água fria e pontos de contribuição de esgoto sanitário, com a instalação de tanque em marmore sintético com a base em alvenaria. | AK23: x
B24: J) | C24: Esgotamento Sanitário (kit fossa/sumidouro): Execução do sistema de tratamento de efluentes domésticos, composto por tanque séptico (fossa séptica) e sumidouro, visando a sedimentação, flotação e digestão anaeróbia da matéria orgânica, seguida pela destinação final via infiltração no solo.
B25: 1.4 Esquadrias | AK25: x
B26: L) | C26: Porta sala: Será feita a instalação de esquadrias de madeira estilo veneziana (folhas de porta, guarnições e ferragens)
B27: M) | C27: Porta cozinha: Será feita a instalação de esquadrias de madeira estilo veneziana (folhas de porta, guarnições e ferragens)
B28: N) | C28: Porta interna quarto: Será feita a instalação de esquadrias de madeira, guarnição e ferragens
B29: O) | C29: Porta interna wc: Será feita a instalação de esquadrias de madeira, guarnição e ferragens | AK29: x
B30: P) | C30: Janela: Será feita a instalação de esquadrias de madeira, guarnição e ferragens | AK30: x
B31: Q) | C31: Grade pega ladrão janela: fabricação e instalação de grades de proteção em ferro, destinadas à segurança de aberturas. Construidas em vergalhões de ferro redondo, dispostos com espaçamento máximo de 10 cm entre eixos, com aplicação de uma demão de fundo anticorrosivo (tipo zarcão).
B32: R) | C32: Grade de ferro: fabricação e instalação de grades de proteção em ferro, destinadas à segurança de aberturas. Construidas em vergalhões de ferro redondo, dispostos com espaçamento máximo de 10 cm entre eixos, com aplicação de uma demão de fundo anticorrosivo (tipo zarcão).
B33: S) | C33: Portão garagem grande: Fabricação e instalação de portão de garagem em ferro, visando garantir a segurança e privacidade, extrutura em perfis de metalon galvanizado, Chapas de ferro tipo labris fixadas por solda elétrica e aplicação de fundo anticorrosivo tipo zarcão.
B34: T) | C34: Portão pequeno: fabricação e instalação de portão pequeno de ferro para entrada do alpendre, destinadas à segurança de aberturas. Construidas em vergalhões de ferro redondo com chapa na parte inferior, dispostos com espaçamento máximo de 10 cm entre eixos, com aplicação de uma demão de fundo anticorrosivo (tipo zarcão). | AK34: x
B35: U | C35: Portão social: Fabricação e instalação de portão social em ferro, visando garantir a segurança e privacidade, extrutura em perfis de metalon galvanizado, ou barra redonda, Chapas de ferro tipo labris fixadas por solda elétrica em todo o portão ou apenas em partes e aplicação de fundo anticorrosivo tipo zarcão.
B36: 1.5 Pintura e Revestimento | AK36: x
B37: V) | C37: Rev. Cerâmico (casa completa): execução de revestimento cerâmico em piso, garantindo a qualidade estética, funcional e a durabilidade do sistema. Observando o uso de argamassa adequada e aplicação de rejunte. | AK37: x
B38: X) | C38: Rev. Cerâmico (banheiro): execução de revestimento cerâmico em piso e parede até a altura de 1,5 m, garantindo a qualidade estética, funcional e a durabilidade do sistema. Observando o uso de argamassa adequada e aplicação de rejunte. | AK38: x
B39: Z) | C39: Rev. Cerâmico (alpendre e area de serviço): execução de revestimento cerâmico em piso, garantindo a qualidade estética, funcional e a durabilidade do sistema. Observando o uso de argamassa adequada e aplicação de rejunte. | AK39: x
B40: AA) | C40: Forro Pvc (casa completa): Instalação de sistema de forro em PVC rígido, fixado sobre estrutura auxiliar, com acabamento em molduras periféricas.
B41: AB) | C41: Forro Pvc (wc): Instalação de sistema de forramento em PVC rígido, fixado sobre estrutura auxiliar, com acabamento em molduras periféricas. | AK41: x
B42: AC) | C42: Pintura: Após a conclusão das intervenções civis, a edificação receberá a aplicação de revestimento de acabamento (pintura) em todas as faces internas e externas. | AK42: x
B43: 1.7 Itens de Acessibilidade | AK43: x
B44: AD) | C44: Barra de apoio: fornecimento e a instalação de barras de apoio, visando garantir a acessibilidade, a segurança e a autonomia de pessoas com deficiência (PcD) ou mobilidade reduzida.
B45: AE) | C45: Corrimão para escada/rampa: fornecimento e a instalação de corrimão de apoio, visando garantir a acessibilidade, a segurança e a autonomia de pessoas com deficiência (PcD) ou mobilidade reduzida.
...

Sheet 4.Reg. Fotografico
B5: ='0. Dados'!F7 -> São José do Capricho, em Flexeiras/AL
B6: =TODAY() -> 46224
B8: Nome do beneficiário | AA8: CPF
B9: ='0. Dados'!D9 -> Angelo Santos | AA9: ='0. Dados'!Z9 -> 11277828431

Sheet 5.Composição analítica_material
E6: ='0. Dados'!F7 -> São José do Capricho, em Flexeiras/AL
B7: =TODAY() -> 46224
B8: Beneficiário: | E8: ='0. Dados'!D9 -> Angelo Santos | F8: CPF: | G8: ='0. Dados'!Z9 -> 11277828431
B9: TOTAL | C9: =I75 -> 50000
B11: Item | C11: Codigo | D11: Fonte | E11: Discriminação de Materiais | F11: Unid. | G11: Quant | H11: Valor Unitário | I11: Total | J11: %
B12: 1. ESTRUTURAL | K12: =IF(AND(F12<>"",G12=0),"","X") -> X
B13: 1.1 | C13: 95240 | D13: SINAPI | E13: Lastro de concreto magro, aplicado em pisos ou radiers, espessura de 5 cm. af_07/2016 | F13: m² | G13: 10 | H13: 19.28 | I13: =H13*G13 -> 192.8 | J13: =(I13*100)/K75 -> 0.3852572 | K13: =IF(AND(F13<>"",G13=0),"","X") -> X
B14: 1.2 | C14: 87702 | D14: SINAPI | E14: Contrapiso em argamassa traço 1:4 (cimento e areia), preparo manual, aplicado em áreas secas sobre laje, não aderido, acabamento não reforçado, espessura 6cm. af_07/2021 | F14: m² | G14: 35 | H14: 63.93 | I14: =H14*G14 -> 2237.55 | J14: =(I14*100)/K75 -> 4.4711216 | K14: =IF(AND(F14<>"",G14=0),"","X") -> X
B15: 1.3 | C15: 103333 | D15: SINAPI | E15: Alvenaria de vedação de blocos ceramicos furados na horizontal de 9X14X19 cm e argamassa de assentamento com preparo manual. AF_12/2021 | F15: m² | G15: 55 | H15: 120.12 | I15: =H15*G15 -> 6606.6 | J15: =(I15*100)/K75 -> 13.201453 | K15: =IF(AND(F15<>"",G15=0),"","X") -> X
C16: 11910 | D16: ORSE | E16: Piso cimentado colorido, diversas cores, desempolado traço 1:5, e = 3 cm, c/junta plastica 3x27mm | F16: m² | G16: 0 | H16: 59.62 | I16: =H16*G16 -> 0 | J16: =(I16*100)/K75 -> 0 | K16: =IF(AND(F16<>"",G16=0),"","X")
B17: 1.4 | C17: 101963 | D17: SINAPI | E17: Laje pré-moldada unidirecional, biapoiada, para piso, enchimento em cerâmica, vigota convencional, altura total da laje (enchimento+capa). af_11/2020_pa (base para cx d'água acima do wc) | F17: m² | G17: 6 | H17: 198.46 | I17: =H17*G17 -> 1190.76 | J17: =(I17*100)/K75 -> 2.3794028 | K17: =IF(AND(F17<>"",G17=0),"","X") -> X
B18: 2. COBERTA | K18: =IF(AND(F18<>"",G18=0),"","X") -> X
B19: 2.1 | C19: 92541 | D19: SINAPI | E19: Trama de madeira composta por ripas, caibros e terças para telhados de ate 2 aguas para telha ceramica capa-canal, incluso transporte vertical. AF_07/2019 | F19: m² | G19: 52 | H19: 68.15 | I19: =H19*G19 -> 3543.8 | J19: =(I19*100)/K75 -> 7.0812991 | K19: =IF(AND(F19<>"",G19=0),"","X") -> X
B20: 2.2 | C20: 94204 | D20: SINAPI | E20: Telhamento com telha ceramica capa-canal, tipo colonial, incluso transporte vertical. AF_07/2019 | F20: m² | G20: =G19 -> 52 | H20: 44.26 | I20: =H20*G20 -> 2301.52 | J20: =(I20*100)/K75 -> 4.5989479 | K20: =IF(AND(F20<>"",G20=0),"","X") -> X
B21: 2.3 | C21: 94221 | D21: SINAPI | E21: Cumeeira para telha cerâmica emboçada com argamassa traço 1:2:9 (cimento, cal e areia) para telhados com até 2 águas, incluso transporte vertical. af_07/2019 | F21: m | G21: 7 | H21: 22.47 | I21: =H21*G21 -> 157.29 | J21: =(I21*100)/K75 -> 0.31430034 | K21: =IF(AND(F21<>"",G21=0),"","X") -> X
B22: 3. INSTALAÇÃO RESIDENCIAL ELÉTRICA | K22: =IF(AND(F22<>"",G22=0),"","X") -> X
B23: 3.1 | C23: 98111 | D23: SINAPI | E23: Caixa de inspeção para aterramento, circular, em polietileno, diâmetro interno = 0,3 m. Af_12/2020 | F23: und | G23: 0 | H23: 50.28 | I23: =H23*G23 -> 0 | J23: =(I23*100)/K75 -> 0 | K23: =IF(AND(F23<>"",G23=0),"","X")
B24: 3.2 | C24: 3290 | D24: ORSE | E24: Aterramento composto de haste de cobre l = 2,40m, interligada com cabo de cobre tipo cordoalha | F24: und | G24: 0 | H24: 125.77 | I24: =H24*G24 -> 0 | J24: =(I24*100)/K75 -> 0 | K24: =IF(AND(F24<>"",G24=0),"","X")
B25: 3.3 | C25: 8174 | D25: ORSE | E25: Grampo de cobre tipo unha c/bucha e parafuso nº10, para fixação de cabo cobre nú | F25: und | G25: 0 | H25: 7.62 | I25: =H25*G25 -> 0 | J25: =(I25*100)/K75 -> 0 | K25: =IF(AND(F25<>"",G25=0),"","X")
B26: 3.4 | C26: 101938 | D26: SINAPI | E26: Caixa de proteção para medidor monofásico de embutir - fornecimento e instalação. Af_10/2020 | F26: und | G26: 0 | H26: 163.62 | I26: =H26*G26 -> 0 | J26: =(I26*100)/K75 -> 0 | K26: =IF(AND(F26<>"",G26=0),"","X")
B27: 3.5 | C27: 101877 | D27: SINAPI | E27: Quadro de distribuição de energia em pvc, de embutir, sem barramento, para 3 disjuntores - fornecimento e instalação. af_10/2020 | F27: und | G27: 0 | H27: 87.13 | I27: =H27*G27 -> 0 | J27: =(I27*100)/K75 -> 0 | K27: =IF(AND(F27<>"",G27=0),"","X")
B28: 3.6 | C28: 101892 | D28: SINAPI | E28: Disjuntor bipolar tipo nema, corrente nominal de 10 até 50a - fornecimento e instalação. af_10/2020 | F28: und | G28: 0 | H28: 77.37 | I28: =H28*G28 -> 0 | J28: =(I28*100)/K75 -> 0 | K28: =IF(AND(F28<>"",G28=0),"","X")
B29: 3.7 | C29: 104473 | D29: SINAPI | E29: Composição paramétrica de ponto elétrico de iluminação, com interruptor simples, em edifício residencial com eletroduto embutido em rasgos nas paredes, incluso tomada, eletroduto, cabo, rasgo e chumbamento (sem luminária e lâmpada). af_11/2022 | F29: und | G29: 0 | H29: 187.97 | I29: =H29*G29 -> 0 | J29: =(I29*100)/K75 -> 0 | K29: =IF(AND(F29<>"",G29=0),"","X")
B30: 3.8 | C30: 104475 | D30: SINAPI | E30: Composição paramétrica de ponto elétrico de tomada de uso geral 2p+t (10a/250v) em edifício residencial com eletroduto embutido em rasgos nas paredes, incluso tomada, eletroduto, cabo, rasgo, quebra e chumbamento. Af_11/2022 | F30: und | G30: 0 | H30: 163.92 | I30: =H30*G30 -> 0 | J30: =(I30*100)/K75 -> 0 | K30: =IF(AND(F30<>"",G30=0),"","X")
B31: 4. INSTALAÇÃO HIDRO SANITARIA | K31: =IF(AND(F31<>"",G31=0),"","X") -> X
B32: 4.1 | C32: Código | D32: Banco | E32: Instalação hidraulica - agua fria | K32: =IF(AND(F32<>"",G32=0),"","X") -> X
B33: 4.1.1 | C33: 2022 | D33: ORSE | E33: Chuveiro simples de plástico (herc ref 1980 ou similar), c/ registro de pressão de pvc | F33: und | G33: 1 | H33: 72.43 | I33: =H33*G33 -> 72.43 | J33: =(I33*100)/K75 -> 0.14473122 | K33: =IF(AND(F33<>"",G33=0),"","X") -> X
B34: 4.1.2 | C34: 102622 | D34: SINAPI | E34: Caixa d´água em polietileno, 500 litros (inclusos tubos, conexões e torneira de bóia) - fornecimento e instalação. af_06/2021 | F34: und | G34: 1 | H34: 579.15 | I34: =H34*G34 -> 579.15 | J34: =(I34*100)/K75 -> 1.1572703 | K34: =IF(AND(F34<>"",G34=0),"","X") -> X
B35: 4.1.3 | C35: 90371 | D35: SINAPI | E35: Registro de esfera, PVC, roscavel, com volante 3/4" - fornecimento e instalação. AF_08/2021 | F35: und | G35: 2 | H35: 24.79 | I35: =H35*G35 -> 49.58 | J35: =(I35*100)/K75 -> 0.099071846 | K35: =IF(AND(F35<>"",G35=0),"","X") -> X
B36: 4.1.4 | C36: 1353 | D36: ORSE | E36: Ponto de água fria embutido, c/material pvc rígido roscável Ø 3/4" | F36: und | G36: 3 | H36: 197.86 | I36: =H36*G36 -> 593.58 | J36: =(I36*100)/K75 -> 1.1861046 | K36: =IF(AND(F36<>"",G36=0),"","X") -> X
B37: 4.2 | C37: Código | D37: Banco | E37: Instalação sanitaria/esgoto | K37: =IF(AND(F37<>"",G37=0),"","X") -> X
B38: 4.2.1 | C38: 104327 | D38: SINAPI | E38: Ralo sifonado redondo, pvc, dn 100 x 40 mm, junta soldável, fornecido e instalado em ramal de descarga ou em ramal de esgoto sanitário. af_08/2022 | F38: uni | G38: 1 | H38: 18.97 | I38: =H38*G38 -> 18.97 | J38: =(I38*100)/K75 -> 0.037906271 | K38: =IF(AND(F38<>"",G38=0),"","X") -> X
B39: 4.2.2 | C39: 1679 | D39: ORSE | E39: Ponto de esgoto com tubo de pvc rígido soldável de Ø 40 mm (lavatórios, mictórios, ralos sifonados, etc...) | F39: uni | G39: 2 | H39: 78.77 | I39: =H39*G39 -> 157.54 | J39: =(I39*100)/K75 -> 0.31479989 | K39: =IF(AND(F39<>"",G39=0),"","X") -> X
B40: 4.2.3 | C40: 1683 | D40: ORSE | E40: Ponto de esgoto com tubo de pvc rígido soldável de Ø 100 mm (vaso sanitário) | F40: uni | G40: 1 | H40: 109.9 | I40: =H40*G40 -> 109.9 | J40: =(I40*100)/K75 -> 0.2196046 | K40: =IF(AND(F40<>"",G40=0),"","X") -> X
B41: 5. ESQUADRIAS | K41: =IF(AND(F41<>"",G41=0),"","X") -> X
B42: 5.1 | C42: 31 | D42: ORSE | E42: Remoção de esquadria de madeira, com ou sem batente | F42: m2 | G42: 0 | H42: 17.47 | I42: =H42*G42 -> 0 | J42: =(I42*100)/K75 -> 0 | K42: =IF(AND(F42<>"",G42=0),"","X")
B43: 5.2 | C43: 90821 | D43: SINAPI | E43: Porta de madeira para pintura, semi-oca (leve ou média), 70x210cm, esp essura de 3,5cm, incluso dobradiças - fornecimento e instalação. Af_12 | F43: uni | G43: 1 | H43: 323.58 | I43: =H43*G43 -> 323.58 | J43: =(I43*100)/K75 -> 0.64658467 | K43: =IF(AND(F43<>"",G43=0),"","X") -> X
B44: 5.3 | C44: 90806 | D44: SINAPI | E44: Batente para porta de madeira, fixação com argamassa, padrão médio | F44: uni | G44: =G43 -> 1 | H44: 435.86 | I44: =H44*G44 -> 435.86 | J44: =(I44*100)/K75 -> 0.87094503 | K44: =IF(AND(F44<>"",G44=0),"","X") -> X
B45: 5.4 | C45: 9179 | D45: ORSE | E45: Janela em madeira mista, tipo com almofadas, de abrir, c/batentes simples (caixilhos) e 1 jogo de alizar, exclusive ferragens - Rev 02_05/2022 | F45: uni | G45: 5 | H45: 352.94 | I45: =H45*G45 -> 1764.7 | J45: =(I45*100)/K75 -> 3.5262623 | K45: =IF(AND(F45<>"",G45=0),"","X") -> X
B46: 5.5 | C46: 91335 | D46: SINAPI | E46: Kit de porta de madeira tipo veneziana, padrão popular, 80x210cm, espessura de 3cm, itens inclusos: dobradiças, montagem e instalação do batente, sem fechadura - fornecimento e instalação. af_12/2019 | F46: uni | G46: 0 | H46: 1684.57 | I46: =H46*G46 -> 0 | J46: =(I46*100)/K75 -> 0 | K46: =IF(AND(F46<>"",G46=0),"","X")
...

Sheet 6.Curva ABC
D6: ='0. Dados'!F7 -> São José do Capricho, em Flexeiras/AL
B7: =TODAY() -> 46224
B11: Beneficiário: | D11: ='0. Dados'!D9 -> Angelo Santos | E11: CPF: | F11: ='0. Dados'!Z9 -> 11277828431
J12: CURVA ABC
B13: Codigo | C13: Fonte | D13: Discriminação de Materiais | E13: Unid. | F13: Quant | G13: Valor Unitário | H13: Total | I13: PRINT | J13: % | K13: Acumulado (%) | L13: Classe
B14: 103333 | C14: SINAPI | D14: Alvenaria de vedação de blocos ceramicos furados na horizontal de 9X14X19 cim e argamassa de assentamento com preparo manual. AF_12/2021 | E14: m² | F14: ='5.Composição analítica_material'!G61 -> 0 | G14: ='5.Composição analítica_material'!H61 -> 120.12 | H14: ='5.Composição analítica_material'!I61 -> 0 | I14: =IF(AND(E14<>"",F14=0),"","X") | J14: =H14/$I$66 -> 0 | K14: =SUM($J$14:J14) -> 0 | L14: =IF(K14<=0.8,"A",IF(K14<=0.95,"B","C")) -> A
B15: 96485 | C15: SINAPI | D15: Forro em réguas de pvc, liso, para ambientes residenciais, inclusive e strutura unidirecional de fixação. Af_08/2023_ps | E15: Alvenaria de vedação de blocos ceramicos furados na horizontal de 9X14X19 cm e argamassa de assentamento com preparo manual. AF_12/2021 | F15: ='5.Composição analítica_material'!G52 -> 120 | G15: ='5.Composição analítica_material'!H52 -> 85.72 | H15: ='5.Composição analítica_material'!I52 -> 10286.4 | I15: =IF(AND(E15<>"",F15=0),"","X") -> X | J15: =H15/$I$66 -> 0.20554511 | K15: =SUM($J$14:J15) -> 0.20554511 | L15: =IF(K15<=0.8,"A",IF(K15<=0.95,"B","C")) -> A
B16: 10615 | C16: ORSE | D16: Revestimento ceramico, 33,5 x 45 cm, Eliane, linha Forma branco AC, aplicado com argamassa industrializada ac-i, rejuntado, exclusive emboço | E16: m² | F16: ='5.Composição analítica_material'!G51 -> 155 | G16: ='5.Composição analítica_material'!H51 -> 62.34 | H16: ='5.Composição analítica_material'!I51 -> 9662.7 | I16: =IF(AND(E16<>"",F16=0),"","X") -> X | J16: =H16/$I$66 -> 0.1930822 | K16: =SUM($J$14:J16) -> 0.3986273 | L16: =IF(K16<=0.8,"A",IF(K16<=0.95,"B","C")) -> A
B17: 91335 | C17: SINAPI | D17: Kit de porta de madeira tipo veneziana, padrão popular, 80x210cm, espessura de 3cm, itens inclusos: dobradiças, montagem e instalação do batente, sem fechadura - fornecimento e instalação. af_12/2019 | E17: uni | F17: ='5.Composição analítica_material'!G46 -> 0 | G17: ='5.Composição analítica_material'!H46 -> 1684.57 | H17: ='5.Composição analítica_material'!I46 -> 0 | I17: =IF(AND(E17<>"",F17=0),"","X") | J17: =H17/$I$66 -> 0 | K17: =SUM($J$14:J17) -> 0.3986273 | L17: =IF(K17<=0.8,"A",IF(K17<=0.95,"B","C")) -> A
B18: 3316 | C18: ORSE | D18: Reboco externo, de parede, com argamassa traço 1:4 (cal / areia), espessura 2,5 cm | E18: m² | F18: ='5.Composição analítica_material'!G62 -> 0 | G18: ='5.Composição analítica_material'!H62 -> 41.67 | H18: ='5.Composição analítica_material'!I62 -> 0 | I18: =IF(AND(E18<>"",F18=0),"","X") | J18: =H18/$I$66 -> 0 | K18: =SUM($J$14:J18) -> 0.3986273 | L18: =IF(K18<=0.8,"A",IF(K18<=0.95,"B","C")) -> A
B19: 103333 | C19: SINAPI | D19: Alvenaria de vedação de blocos ceramicos furados na horizontal de 9X14X19 cm e argamassa de assentamento com preparo manual. AF_12/2021 | E19: m2 | F19: ='5.Composição analítica_material'!G15 -> 55 | G19: ='5.Composição analítica_material'!H15 -> 120.12 | H19: ='5.Composição analítica_material'!I15 -> 6606.6 | I19: =IF(AND(E19<>"",F19=0),"","X") -> X | J19: =H19/$I$66 -> 0.13201453 | K19: =SUM($J$14:J19) -> 0.53064183 | L19: =IF(K19<=0.8,"A",IF(K19<=0.95,"B","C")) -> A
B20: 93358 | C20: SINAPI | D20: Escavação manual de vala com profundidade menor ou igual a 1,30 m. af_02/2021 | E20: m3 | F20: ='5.Composição analítica_material'!G60 -> 0 | G20: ='5.Composição analítica_material'!H60 -> 85.91 | H20: ='5.Composição analítica_material'!I60 -> 0 | I20: =IF(AND(E20<>"",F20=0),"","X") | J20: =H20/$I$66 -> 0 | K20: =SUM($J$14:J20) -> 0.53064183 | L20: =IF(K20<=0.8,"A",IF(K20<=0.95,"B","C")) -> A
B21: 2287 | C21: ORSE | D21: Pintura de acabamento com aplicação de 02 demãos de tinta PVA latex para exteriores - cores convencionais | E21: m² | F21: ='5.Composição analítica_material'!G48 -> 265 | G21: ='5.Composição analítica_material'!H48 -> 17.44 | H21: ='5.Composição analítica_material'!I48 -> 4621.6 | I21: =IF(AND(E21<>"",F21=0),"","X") -> X | J21: =H21/$I$66 -> 0.092349827 | K21: =SUM($J$14:J21) -> 0.62299166 | L21: =IF(K21<=0.8,"A",IF(K21<=0.95,"B","C")) -> A
B22: 92541 | C22: SINAPI | D22: Trama de madeira composta por ripas, caibros e terças para telhados de ate 2 aguas para telha ceramica capa-canal, incluso transporte vertical. AF_07/2019 | E22: m² | F22: ='5.Composição analítica_material'!G19 -> 52 | G22: ='5.Composição analítica_material'!H19 -> 68.15 | H22: ='5.Composição analítica_material'!I19 -> 3543.8 | I22: =IF(AND(E22<>"",F22=0),"","X") -> X | J22: =H22/$I$66 -> 0.070812991 | K22: =SUM($J$14:J22) -> 0.69380465 | L22: =IF(K22<=0.8,"A",IF(K22<=0.95,"B","C")) -> A
B23: 3316 | C23: ORSE | D23: Reboco externo, de parede, com argamassa traço 1:4 (cal / areia), espessura 2,5 cm | E23: m² | F23: ='5.Composição analítica_material'!G50 -> 60 | G23: ='5.Composição analítica_material'!H50 -> 41.67 | H23: ='5.Composição analítica_material'!I50 -> 2500.2 | I23: =IF(AND(E23<>"",F23=0),"","X") -> X | J23: =H23/$I$66 -> 0.049959546 | K23: =SUM($J$14:J23) -> 0.7437642 | L23: =IF(K23<=0.8,"A",IF(K23<=0.95,"B","C")) -> A
B24: 94204 | C24: SINAPI | D24: Telhamento com telha ceramica capa-canal, tipo colonial, incluso transporte vertical. AF_07/2019 | E24: m² | F24: ='5.Composição analítica_material'!G20 -> 52 | G24: ='5.Composição analítica_material'!H20 -> 44.26 | H24: ='5.Composição analítica_material'!I20 -> 2301.52 | I24: =IF(AND(E24<>"",F24=0),"","X") -> X | J24: =H24/$I$66 -> 0.045989479 | K24: =SUM($J$14:J24) -> 0.78975368 | L24: =IF(K24<=0.8,"A",IF(K24<=0.95,"B","C")) -> A
B25: 92541 | C25: SINAPI | D25: Trama de madeira composta por ripas, caibros e terças para telhados de ate 2 aguas para telha ceramica capa-canal, incluso transporte vertical. AF_07/2019 | E25: m² | F25: ='5.Composição analítica_material'!G64 -> 0 | G25: ='5.Composição analítica_material'!H64 -> 68.15 | H25: ='5.Composição analítica_material'!I64 -> 0 | I25: =IF(AND(E25<>"",F25=0),"","X") | J25: =H25/$I$66 -> 0 | K25: =SUM($J$14:J25) -> 0.78975368 | L25: =IF(K25<=0.8,"A",IF(K25<=0.95,"B","C")) -> A
B26: 87702 | C26: SINAPI | D26: Contrapiso em argamassa traço 1:4 (cimento e areia), preparo manual, aplicado em áreas secas sobre laje, não aderido, acabamento não reforçado, espessura 6cm. af_07/2021 | E26: m² | F26: ='5.Composição analítica_material'!G14 -> 35 | G26: ='5.Composição analítica_material'!H14 -> 63.93 | H26: ='5.Composição analítica_material'!I14 -> 2237.55 | I26: =IF(AND(E26<>"",F26=0),"","X") -> X | J26: =H26/$I$66 -> 0.044711216 | K26: =SUM($J$14:J26) -> 0.83446489 | L26: =IF(K26<=0.8,"A",IF(K26<=0.95,"B","C")) -> B
B27: 104473 | C27: SINAPI | D27: Composição paramétrica de ponto elétrico de iluminação, com interruptor simples, em edifício residencial com eletroduto embutido em rasgos nas paredes, incluso tomada, eletroduto, cabo, rasgo e chumbamento (sem luminária e lâmpada). af_11/2022 | E27: und | F27: ='5.Composição analítica_material'!G29 -> 0 | G27: ='5.Composição analítica_material'!H29 -> 187.97 | H27: ='5.Composição analítica_material'!I29 -> 0 | I27: =IF(AND(E27<>"",F27=0),"","X") | J27: =H27/$I$66 -> 0 | K27: =SUM($J$14:J27) -> 0.83446489 | L27: =IF(K27<=0.8,"A",IF(K27<=0.95,"B","C")) -> B
B28: 9179 | C28: ORSE | D28: Janela em madeira mista, tipo com almofadas, de abrir, c/batentes simples (caixilhos) e 1 jogo de alizar, exclusive ferragens - Rev 02_05/2022 | E28: uni | F28: ='5.Composição analítica_material'!G45 -> 5 | G28: ='5.Composição analítica_material'!H45 -> 352.94 | H28: ='5.Composição analítica_material'!I45 -> 1764.7 | I28: =IF(AND(E28<>"",F28=0),"","X") -> X | J28: =H28/$I$66 -> 0.035262623 | K28: =SUM($J$14:J28) -> 0.86972752 | L28: =IF(K28<=0.8,"A",IF(K28<=0.95,"B","C")) -> B
B29: 104475 | C29: SINAPI | D29: Composição paramétrica de ponto elétrico de tomada de uso geral 2p+t (10a/250v) em edifício residencial com eletroduto embutido em rasgos nas paredes, incluso tomada, eletroduto, cabo, rasgo, quebra e chumbamento. Af_11/2022 | E29: und | F29: ='5.Composição analítica_material'!G30 -> 0 | G29: ='5.Composição analítica_material'!H30 -> 163.92 | H29: ='5.Composição analítica_material'!I30 -> 0 | I29: =IF(AND(E29<>"",F29=0),"","X") | J29: =H29/$I$66 -> 0 | K29: =SUM($J$14:J29) -> 0.86972752 | L29: =IF(K29<=0.8,"A",IF(K29<=0.95,"B","C")) -> B
B30: 8900 | C30: ORSE | D30: Portão de ferro de abrir com uma folha, com barra quadrada de 1/2" na vertical, uma barra de quadrada de 1/2" na horizontal e quadro com barra de ferro de 1/2", inclusive dobradiças, ferrolhos e chumbadores com parafusos | E30: m² | F30: ='5.Composição analítica_material'!G66 -> 2 | G30: ='5.Composição analítica_material'!H66 -> 658.15 | H30: ='5.Composição analítica_material'!I66 -> 1316.3 | I30: =IF(AND(E30<>"",F30=0),"","X") -> X | J30: =H30/$I$66 -> 0.026302596 | K30: =SUM($J$14:J30) -> 0.89603011 | L30: =IF(K30<=0.8,"A",IF(K30<=0.95,"B","C")) -> B
B31: 94204 | C31: SINAPI | D31: Telhamento com telha ceramica capa-canal, tipo colonial, incluso transporte vertical. AF_07/2019 | E31: m² | F31: ='5.Composição analítica_material'!G65 -> 0 | G31: ='5.Composição analítica_material'!H65 -> 44.26 | H31: ='5.Composição analítica_material'!I65 -> 0 | I31: =IF(AND(E31<>"",F31=0),"","X") | J31: =H31/$I$66 -> 0 | K31: =SUM($J$14:J31) -> 0.89603011 | L31: =IF(K31<=0.8,"A",IF(K31<=0.95,"B","C")) -> B
B32: 101963 | C32: SINAPI | D32: Laje pré-moldada unidirecional, biapoiada, para piso, enchimento em cerâmica, vigota convencional, altura total da laje (enchimento+capa). af_11/2020_pa (base para cx d'água acima do wc) | E32: m2 | F32: ='5.Composição analítica_material'!G17 -> 6 | G32: ='5.Composição analítica_material'!H17 -> 198.46 | H32: ='5.Composição analítica_material'!I17 -> 1190.76 | I32: =IF(AND(E32<>"",F32=0),"","X") -> X | J32: =H32/$I$66 -> 0.023794028 | K32: =SUM($J$14:J32) -> 0.91982414 | L32: =IF(K32<=0.8,"A",IF(K32<=0.95,"B","C")) -> B
B33: 1353 | C33: ORSE | D33: Ponto de água fria embutido, c/material pvc rígido roscável Ø 3/4" | E33: und | F33: ='5.Composição analítica_material'!G36 -> 3 | G33: ='5.Composição analítica_material'!H36 -> 197.86 | H33: ='5.Composição analítica_material'!I36 -> 593.58 | I33: =IF(AND(E33<>"",F33=0),"","X") -> X | J33: =H33/$I$66 -> 0.011861046 | K33: =SUM($J$14:J33) -> 0.93168519 | L33: =IF(K33<=0.8,"A",IF(K33<=0.95,"B","C")) -> B
B34: 102622 | C34: SINAPI | D34: Caixa d´água em polietileno, 500 litros (inclusos tubos, conexões e torneira de bóia) - fornecimento e instalação. af_06/2021 | E34: und | F34: ='5.Composição analítica_material'!G34 -> 1 | G34: ='5.Composição analítica_material'!H34 -> 579.15 | H34: ='5.Composição analítica_material'!I34 -> 579.15 | I34: =IF(AND(E34<>"",F34=0),"","X") -> X | J34: =H34/$I$66 -> 0.011572703 | K34: =SUM($J$14:J34) -> 0.94325789 | L34: =IF(K34<=0.8,"A",IF(K34<=0.95,"B","C")) -> B
B35: 4765 | C35: ORSE | D35: Vaso sanitario c/caixa de descarga acoplada, linha saveiro, CELITE ou similar, c/ engate pvc, assento universal AMANCO ou similar | E35: und | F35: ='5.Composição analítica_material'!G55 -> 1 | G35: ='5.Composição analítica_material'!H55 -> 512.54 | H35: ='5.Composição analítica_material'!I55 -> 512.54 | I35: =IF(AND(E35<>"",F35=0),"","X") -> X | J35: =H35/$I$66 -> 0.010241687 | K35: =SUM($J$14:J35) -> 0.95349958 | L35: =IF(K35<=0.8,"A",IF(K35<=0.95,"B","C")) -> C
B36: 90806 | C36: SINAPI | D36: Batente para porta de madeira, fixação com argamassa, padrão médio - f | E36: uni | F36: ='5.Composição analítica_material'!G44 -> 1 | G36: ='5.Composição analítica_material'!H44 -> 435.86 | H36: ='5.Composição analítica_material'!I44 -> 435.86 | I36: =IF(AND(E36<>"",F36=0),"","X") -> X | J36: =H36/$I$66 -> 0.0087094503 | K36: =SUM($J$14:J36) -> 0.96220903 | L36: =IF(K36<=0.8,"A",IF(K36<=0.95,"B","C")) -> C
B37: 86929 | C37: SINAPI | D37: Tanque de mármore sintético suspenso, 22l ou equivalente, incluso sifão flexível em pvc, válvula plástica e torneira de metal cromado padrão popular - fornecimento e instalação. af_01/2020 | E37: und | F37: ='5.Composição analítica_material'!G57 -> 1 | G37: ='5.Composição analítica_material'!H57 -> 324.83 | H37: ='5.Composição analítica_material'!I57 -> 324.83 | I37: =IF(AND(E37<>"",F37=0),"","X") -> X | J37: =H37/$I$66 -> 0.0064908245 | K37: =SUM($J$14:J37) -> 0.96869985 | L37: =IF(K37<=0.8,"A",IF(K37<=0.95,"B","C")) -> C
B38: 95240 | C38: SINAPI | D38: Lastro de concreto magro, aplicado em pisos ou radiers, espessura de 5 cm. af_07/2016 | E38: m² | F38: ='5.Composição analítica_material'!G63 -> 0 | G38: ='5.Composição analítica_material'!H63 -> 19.28 | H38: ='5.Composição analítica_material'!I63 -> 0 | I38: =IF(AND(E38<>"",F38=0),"","X") | J38: =H38/$I$66 -> 0 | K38: =SUM($J$14:J38) -> 0.96869985 | L38: =IF(K38<=0.8,"A",IF(K38<=0.95,"B","C")) -> C
B39: 90821 | C39: SINAPI | D39: Porta de madeira para pintura, semi-oca (leve ou média), 70x210cm, esp essura de 3,5cm, incluso dobradiças - fornecimento e instalação. Af_12 | E39: uni | F39: ='5.Composição analítica_material'!G43 -> 1 | G39: ='5.Composição analítica_material'!H43 -> 323.58 | H39: ='5.Composição analítica_material'!I43 -> 323.58 | I39: =IF(AND(E39<>"",F39=0),"","X") -> X | J39: =H39/$I$66 -> 0.0064658467 | K39: =SUM($J$14:J39) -> 0.9751657 | L39: =IF(K39<=0.8,"A",IF(K39<=0.95,"B","C")) -> C
B40: 2146 | C40: ORSE | D40: Lavatório louça, sem coluna, padrão popular, c/ válvula, sifão, engate e torneira herc ref.1994, todos em plástico, inclusive conj. de fixação ou similares - Rev 03 | E40: und | F40: ='5.Composição analítica_material'!G56 -> 1 | G40: ='5.Composição analítica_material'!H56 -> 284.71 | H40: ='5.Composição analítica_material'!I56 -> 284.71 | I40: =IF(AND(E40<>"",F40=0),"","X") -> X | J40: =H40/$I$66 -> 0.0056891378 | K40: =SUM($J$14:J40) -> 0.98085484 | L40: =IF(K40<=0.8,"A",IF(K40<=0.95,"B","C")) -> C
B41: 4890 | C41: ORSE | D41: Pia de cozinha com bancada em mármore sintético, dim 1.20x0.50, com 01 cuba, sifão, válvula e torneira todos de plástico, assentada.. | E41: und | F41: ='5.Composição analítica_material'!G54 -> 0 | G41: ='5.Composição analítica_material'!H54 -> 306.23 | H41: ='5.Composição analítica_material'!I54 -> 0 | I41: =IF(AND(E41<>"",F41=0),"","X") | J41: =H41/$I$66 -> 0 | K41: =SUM($J$14:J41) -> 0.98085484 | L41: =IF(K41<=0.8,"A",IF(K41<=0.95,"B","C")) -> C
B42: 87878 | C42: SINAPI | D42: Chapisco aplicado em alvenarias e estruturas de concreto internas, com colher de pedreiro. Argamassa traço 1:3 com preparo manual. Af_10/20 | E42: m² | F42: ='5.Composição analítica_material'!G49 -> 40 | G42: ='5.Composição analítica_material'!H49 -> 4.99 | H42: ='5.Composição analítica_material'!I49 -> 199.6 | I42: =IF(AND(E42<>"",F42=0),"","X") -> X | J42: =H42/$I$66 -> 0.0039884511 | K42: =SUM($J$14:J42) -> 0.98484329 | L42: =IF(K42<=0.8,"A",IF(K42<=0.95,"B","C")) -> C
B43: 31 | C43: ORSE | D43: Remoção de esquadria de madeira, com ou sem batente | E43: m2 | F43: ='5.Composição analítica_material'!G42 -> 0 | G43: ='5.Composição analítica_material'!H42 -> 17.47 | H43: ='5.Composição analítica_material'!I42 -> 0 | I43: =IF(AND(E43<>"",F43=0),"","X") | J43: =H43/$I$66 -> 0 | K43: =SUM($J$14:J43) -> 0.98484329 | L43: =IF(K43<=0.8,"A",IF(K43<=0.95,"B","C")) -> C
B44: 12214 | C44: ORSE | D44: Rampa padrão para acesso de deficientes a passeio público, em concreto simples Fck=25MPa, desempolada, com pintura indicativa em novacor, 02 demãos | E44: uni | F44: ='5.Composição analítica_material'!G73 -> 0 | G44: ='5.Composição analítica_material'!H73 -> 384.21 | H44: ='5.Composição analítica_material'!I73 -> 0 | I44: =IF(AND(E44<>"",F44=0),"","X") | J44: =H44/$I$66 -> 0 | K44: =SUM($J$14:J44) -> 0.98484329 | L44: =IF(K44<=0.8,"A",IF(K44<=0.95,"B","C")) -> C
B45: 101892 | C45: SINAPI | D45: Disjuntor bipolar tipo nema, corrente nominal de 10 até 50a - fornecimento e instalação. af_10/2020 | E45: und | F45: ='5.Composição analítica_material'!G28 -> 0 | G45: ='5.Composição analítica_material'!H28 -> 77.37 | H45: ='5.Composição analítica_material'!I28 -> 0 | I45: =IF(AND(E45<>"",F45=0),"","X") | J45: =H45/$I$66 -> 0 | K45: =SUM($J$14:J45) -> 0.98484329 | L45: =IF(K45<=0.8,"A",IF(K45<=0.95,"B","C")) -> C
B46: 95240 | C46: SINAPI | D46: Lastro de concreto magro, aplicado em pisos ou radiers, espessura de 5 cm. af_07/2016 | E46: m² | F46: ='5.Composição analítica_material'!G13 -> 10 | G46: ='5.Composição analítica_material'!H13 -> 19.28 | H46: ='5.Composição analítica_material'!I13 -> 192.8 | I46: =IF(AND(E46<>"",F46=0),"","X") -> X | J46: =H46/$I$66 -> 0.003852572 | K46: =SUM($J$14:J46) -> 0.98869586 | L46: =IF(K46<=0.8,"A",IF(K46<=0.95,"B","C")) -> C
B47: 1679 | C47: ORSE | D47: Ponto de esgoto com tubo de pvc rígido soldável de Ø 40 mm (lavatórios, mictórios, ralos sifonados, etc...) | E47: uni | F47: ='5.Composição analítica_material'!G39 -> 2 | G47: ='5.Composição analítica_material'!H39 -> 78.77 | H47: ='5.Composição analítica_material'!I39 -> 157.54 | I47: =IF(AND(E47<>"",F47=0),"","X") -> X | J47: =H47/$I$66 -> 0.0031479989 | K47: =SUM($J$14:J47) -> 0.99184386 | L47: =IF(K47<=0.8,"A",IF(K47<=0.95,"B","C")) -> C
B48: 101938 | C48: SINAPI | D48: Caixa de proteção para medidor monofásico de embutir - fornecimento e instalação. Af_10/2020 | E48: und | F48: ='5.Composição analítica_material'!G26 -> 0 | G48: ='5.Composição analítica_material'!H26 -> 163.62 | H48: ='5.Composição analítica_material'!I26 -> 0 | I48: =IF(AND(E48<>"",F48=0),"","X") | J48: =H48/$I$66 -> 0 | K48: =SUM($J$14:J48) -> 0.99184386 | L48: =IF(K48<=0.8,"A",IF(K48<=0.95,"B","C")) -> C
...

Sheet 7. Laudo de Habitabitabilidade
B5: OBJETIVO
B6: O presente Laudo Técnico visa atender às exigências da Instrução Normativa INCRA nº 139/2023, tendo por finalidade atestar a viabilidade técnica para a reforma da Unidade Habitacional. O diagnóstico busca garantir que a edificação, após as intervenções propostas, reúna as condições indispensáveis de habitabilidade, salubridade e segurança para a residência rural, conforme os parâmetros técnicos detalhados a seguir.
B8: DADOS DA UNIDADE HABITACIONAL
B9: Projeto de Assentamento e município: | P9: ='0. Dados'!F7 -> São José do Capricho, em Flexeiras/AL
B10: Beneficiários: | H10: ='0. Dados'!D9 -> Angelo Santos | S10: CPF | U10: ='0. Dados'!Z9 -> 11277828431
B11: Sipra: | F11: ='0. Dados'!AA7 -> AL018600000007
B12: Data da vistoria: | I12: ='0. Dados'!X13 -> 2026-07-21
B14: TÉCNICO RESPONSÁVEL
B15: Nome: Antonio Cleverson da Costa Silva
B16: Habilitação: Engenheiro Civil
B17: Entidade: Instituto Centro de Educação e Desenvolvimento Sustentável - ICEDS
B19: CONCLUSÃO
B20: O presente Laudo Técnico atesta que a unidade habitacional supracitada apresenta os requisitos fundamentais de estabilidade e segurança. Conclui-se que o imóvel é passível de plena habitabilidade e salubridade mediante a aplicação do Crédito Instalação (Modalidade Reforma). Os recursos destinados à aquisição de materiais e contratação de serviços de engenharia visam a correção de patologias, reforma e/ou ampliação da área útil e o aprimoramento das condições de conforto térmico e higiênico da edificação, em conformidade com o Projeto Simplificado anexo.
B22: ='0. Dados'!F7 -> São José do Capricho, em Flexeiras/AL
B23: =TODAY() -> 46224
D25: _________________________________
C26: Antonio Cleverson da Costa Silva
C27: Engenheiro Civil
C28: CREA 021697043-1

Sheet Memoria Calc
B1: Alpendre Frontal/fundos | E1: Quarto | H1: Cozinha | K1: Banheiro | P1: Fossa + Sumidouro (frente 2,5 / comprimento 3,8 / profundidade 2,95) piso devera sempre 2,60
B2: Frente (menor) | C2: 0 | E2: Frente (menor) | F2: 0 | H2: Frente (menor) | I2: 0 | K2: Frente (menor) | L2: 0 | P2: Frente (menor) | Q2: 0
B3: Comprimento (maior) | C3: 0 | E3: Comprimento (maior) | F3: 0 | H3: Comprimento (maior) | I3: 0 | K3: Comprimento (maior) | L3: 0 | P3: Comprimento (maior) | Q3: 0
B4: Area | C4: =C2*C3 -> 0 | E4: Area | F4: =F2*F3 -> 0 | H4: Area | I4: =I2*I3 -> 0 | K4: Area | L4: =L2*L3 -> 0 | P4: Profundidade | Q4: 0
B5: Perimetro | C5: =(C2*2)+C3 -> 0 | E5: Perimetro | F5: =(F2*2)+F3 -> 0 | H5: Perimetro | I5: =(I2*2)+I3 -> 0 | K5: Perimetro | L5: =(L2*2)+(L3*2) -> 0 | N5: =L2+(L3*2) -> 0 | P5: Perimetro | Q5: =(Q2*2)+(Q3*2) -> 0
B6: Escavação manual | C6: =C5*0.4*0.4 -> 0 | E6: Escavação manual | F6: =F5*0.4*0.4 -> 0 | H6: Escavação manual | I6: =I5*0.4*0.4 -> 0 | K6: Escavação manual | L6: =N5*0.4*0.4 -> 0 | P6: Escavação manual | Q6: =Q2*Q3*Q4 -> 0
B7: Alvenaria | C7: =C5+(C5*0.4) -> 0 | E7: Alvenaria | F7: =(F5*2.5)+(F5*0.4) -> 0 | H7: Alvenaria | I7: =I5+(I5*0.4) -> 0 | K7: Alvenaria | L7: =L5*2.5 -> 0 | P7: Alvenaria | Q7: =Q5*Q4 -> 0
B8: Reboco | C8: =C7*2 -> 0 | E8: Reboco | F8: =F5*2 -> 0 | H8: Reboco | I8: =I5*2 -> 0 | K8: Reboco | L8: =L7*2 -> 0 | P8: Laje | Q8: =Q3*Q4 -> 0
B9: Lastro de concreto | C9: =C4 -> 0 | E9: Lastro de concreto | F9: =F4 -> 0 | H9: Lastro de concreto | I9: =I4 -> 0 | K9: Lastro de concreto | L9: =L4 -> 0 | P9: Lastro de concreto | Q9: 0
B10: Trama de Madeira | C10: =C4 -> 0 | E10: Trama de Madeira | F10: =F4 -> 0 | H10: Trama de Madeira | I10: =I4 -> 0 | K10: Trama de Madeira | L10: =L4 -> 0 | P10: Reboco | Q10: =Q4*Q5 -> 0
B11: Telhamento | C11: =C4 -> 0 | E11: Telhamento | F11: =F4 -> 0 | H11: Telhamento | I11: =I4 -> 0 | K11: Telhamento | L11: =L4 -> 0
E12: Porta | F12: 1 | H12: ponto eletrico | I12: 1 | K12: ponto eletrico | L12: 1
B13: Alpendre lateral | E13: Caixa de porta | F13: 1 | H13: interruptor | I13: 1 | K13: interruptor | L13: 1
B14: Frente (menor) | C14: 0 | E14: ponto eletrico | F14: 1 | H14: tomada | I14: 2 | K14: Ponto de Agua | L14: 3
B15: Comprimento (maior) | C15: 0 | E15: interruptor | F15: 1 | H15: Ponto de Agua | I15: 1 | K15: Ponto de Esgoto | L15: 2
B16: Area | C16: =C14*C15 -> 0 | E16: tomada | F16: 2 | H16: Ponto de Esgoto | I16: 1 | K16: Ralo Sanfonado | L16: 1
B17: Perimetro | C17: =(C14*2)+C15 -> 0 | H17: Ralo Sanfonado | I17: 1 | K17: Lavatorio | L17: 1
B18: Escavação manual | C18: =C17*0.4*0.4 -> 0 | H18: pia | I18: 1 | K18: Ralo 100 | L18: 1
B19: Alvenaria | C19: =C17+(C17*0.4) -> 0 | E19: Ceramica Casa | K19: Vaso sanitario | L19: 1
B20: Reboco | C20: =C19*2 -> 0 | E20: frente | F20: 0 | H20: Ceramica Banheiro | K20: Ceramica | L20: =L4+(L5*1.5) -> 0 | M20: =(L20*15)/100 -> 0
B21: Lastro de concreto | C21: =C16 -> 0 | E21: comprimento | F21: 0 | H21: frente | I21: 0 | K21: Ceramica + 15% | L21: =L20+M20 -> 0
B22: Trama de Madeira | C22: =C16 -> 0 | E22: area | F22: =F20*F21 -> 0 | H22: comprimento | I22: 0
B23: Telhamento | C23: =C16 -> 0 | E23: percentual | F23: 15 | H23: area | I23: =I21*I22 -> 0
E24: total | F24: =((F22*F23)/100)+F22 -> 0 | H24: Perimetro | I24: =(I21*2)+(I22*2) -> 0
B25: Alpendre Frontal + lateral + fossa septca + wc | H25: total | I25: =I23+(I24*1.5) -> 0
B26: Escavação manual | C26: =C6+C18+Q6+L6 -> 0 | H26: indice de perda (%) | I26: 15
B27: Alvenaria | C27: =C7+C19+Q7+L7 -> 0 | E27: casa | F27: =F24 -> 0 | I27: =(I25*I26)/100 -> 0
B28: Reboco | C28: =C8+C20+Q10+L8 -> 0 | E28: banheiro | F28: =I28 -> 0 | H28: total | I28: =I27+I25 -> 0
B29: Lastro de concreto | C29: =C9+C21+Q9+L9 -> 0 | E29: total | F29: =SUM(F27:F28) -> 0
B30: Trama de Madeira | C30: =C10+C22+L10 -> 0
B31: Telhamento | C31: =C11+C23+L11 -> 0
B32: ponto eletrico | C32: =L12 -> 1
B33: interruptor | C33: =L13 -> 1
B34: Ponto de Agua | C34: =L14 -> 3
B35: Ponto de Esgoto | C35: =L15 -> 2
B36: Ralo Sanfonado | C36: =L16 -> 1
B37: Lavatorio | C37: =L17 -> 1
B38: Ralo 100 | C38: =L18 -> 1
B39: Vaso sanitario | C39: =L19 -> 1
B40: Ceramica + 15% | C40: =L21 -> 0

Sheet Ateste
B4: Beneficiario: | C4: {='0. Dados'!D9:P9} -> Angelo Santos | D4: 0 | E4: 0 | F4: 0 | G4: 0 | H4: 0 | I4: 0 | J4: 0 | K4: 0 | L4: 0 | M4: 0 | N4: 0 | O4: 0
B6: Assentamento: | C6: {='0. Dados'!F7:Q7} -> São José do Capricho, em Flexeiras/AL | D6: 0 | E6: 0 | F6: 0 | G6: 0 | H6: 0 | I6: 0 | J6: 0 | K6: 0 | L6: 0 | M6: 0 | N6: 0
B8: Cod Sipra: | C8: {='0. Dados'!AA7:AI7} -> AL018600000007 | D8: 0 | E8: 0 | F8: 0 | G8: 0 | H8: 0 | I8: 0 | J8: 0 | K8: 0
B10: CPF: | C10: {='0. Dados'!Z9:AI9} -> 11277828431 | D10: 0 | E10: 0 | F10: 0 | G10: 0 | H10: 0 | I10: 0 | J10: 0 | K10: 0 | L10: 0
C12: Descrição do Serviço | D12: Valor | F12: Executado
D13: (R$) | E13: % | F13: %
C14: ='5.Composição analítica_material'!B12 -> 1. ESTRUTURAL | D14: ='5.Composição analítica_material'!I13+'5.Composição analítica_material'!I14+'5.Composição analítica_material'!I15+'5.Composição analítica_material'!I16+'5.Composição analítica_material'!I17 -> 10227.71 | E14: =D14*100/D23 -> 20.437235 | F14: =E23 -> 100
C15: ='5.Composição analítica_material'!B18 -> 2. COBERTA | D15: ='5.Composição analítica_material'!I19+'5.Composição analítica_material'!I20+'5.Composição analítica_material'!I21 -> 6002.61 | E15: =D15*100/D23 -> 11.994547
C16: ='5.Composição analítica_material'!B22 -> 3. INSTALAÇÃO RESIDENCIAL ELÉTRICA | D16: ='5.Composição analítica_material'!I23+'5.Composição analítica_material'!I24+'5.Composição analítica_material'!I25+'5.Composição analítica_material'!I26+'5.Composição analítica_material'!I27+'5.Composição analítica_material'!I28+'5.Composição analítica_material'!I29+'5.Composição analítica_material'!I30 -> 0 | E16: =D16*100/D23 -> 0
C17: ='5.Composição analítica_material'!B31 -> 4. INSTALAÇÃO HIDRO SANITARIA | D17: ='5.Composição analítica_material'!I33+'5.Composição analítica_material'!I34+'5.Composição analítica_material'!I35+'5.Composição analítica_material'!I36+'5.Composição analítica_material'!I38+'5.Composição analítica_material'!I39+'5.Composição analítica_material'!I40 -> 1581.15 | E17: =D17*100/D23 -> 3.1594887
C18: ='5.Composição analítica_material'!B41 -> 5. ESQUADRIAS | D18: ='5.Composição analítica_material'!I42+'5.Composição analítica_material'!I43+'5.Composição analítica_material'!I44+'5.Composição analítica_material'!I45+'5.Composição analítica_material'!I46 -> 2524.14 | E18: =D18*100/D23 -> 5.043792
C19: ='5.Composição analítica_material'!B47 -> 6. PINTURA E REVESTIMENTO | D19: ='5.Composição analítica_material'!I48+'5.Composição analítica_material'!I49+'5.Composição analítica_material'!I50+'5.Composição analítica_material'!I51+'5.Composição analítica_material'!I52 -> 27270.5 | E19: =D19*100/D23 -> 54.492513
C20: ='5.Composição analítica_material'!B53 -> 7. EQUIPAMENTOS | D20: ='5.Composição analítica_material'!I54+'5.Composição analítica_material'!I55+'5.Composição analítica_material'!I56+'5.Composição analítica_material'!I57 -> 1122.08 | E20: =D20*100/D23 -> 2.2421649
C21: ='5.Composição analítica_material'!B58 -> 8. AMPLIAÇÃO/REPAROS | D21: ='5.Composição analítica_material'!I59+'5.Composição analítica_material'!I60+'5.Composição analítica_material'!I61+'5.Composição analítica_material'!I62+'5.Composição analítica_material'!I63+'5.Composição analítica_material'!I64+'5.Composição analítica_material'!I65+'5.Composição analítica_material'!I66+'5.Composição analítica_material'!I67+'5.Composição analítica_material'!I68+'5.Composição analítica_material'!I69 -> 1316.3 | E21: =D21*100/D23 -> 2.6302596
C22: ='5.Composição analítica_material'!B70 -> 9. EQUIPAMENTOS PARA ACESSIBILIDADE DE LOCOMOÇÃO | D22: ='5.Composição analítica_material'!I71+'5.Composição analítica_material'!I72+'5.Composição analítica_material'!I73 -> 0 | E22: =D22*100/D23 -> 0
C23: TOTAL | D23: =SUM(D14:D22) -> 50044.49 | E23: =SUM(E14:E22) -> 100
B25: Termo de Recebimento Definitivo de Obras e Reformas
B26: Declaro, para os devidos fins de direito, que após vistoria minuciosa realizada no imóvel e em suas áreas comuns, confirmo o recebimento da reforma em conformidade com as especificações técnicas, projetos e memorial descritivo apresentados. Atesto a inexistência de vícios ou defeitos aparentes nesta data. Doravante, assumo a total responsabilidade pela guarda e manutenção do imóvel, dando por cumpridas todas as obrigações contratuais do Instituto Centro de Educação e Desenvolvimento Sustentável - ICEDS
E27: ='0. Dados'!F7 -> São José do Capricho, em Flexeiras/AL
E28: =TODAY() -> 46224
B31: _______________________________________ | D31: _______________________________________
B32: Responsavel Técnico | D32: =C4 -> Angelo Santos
B33: Antonio Cleverson da Costa Silva | D33: =C10 -> 11277828431
B34: CREA 021697043-1 | D34: Beneficiario
